<?xml version="1.0" encoding="utf-8"?>
<!-- This URDF was automatically created by SolidWorks to URDF Exporter! Originally created by Stephen Brawner (brawner@gmail.com) 
     Commit Version: 1.6.0-4-g7f85cfe  Build Version: 1.6.7995.38578
     For more information, please see http://wiki.ros.org/sw_urdf_exporter -->
<robot
  name="biped_ab">
  <link
    name="base_link">
    <inertial>
      <origin
        xyz="0.0627679994949339 -0.120701728364036 0.118390187178668"
        rpy="0 0 0" />
      <mass
        value="0.171395163597277" />
      <inertia
        ixx="8.15365300587951E-05"
        ixy="-3.8043709313984E-07"
        ixz="-5.60903798702702E-07"
        iyy="0.000195030559061584"
        iyz="-5.55463363232957E-06"
        izz="0.000139361066214885" />
    </inertial>
    <visual>
      <origin
        xyz="0 0 0"
        rpy="0 0 0" />
      <geometry>
        <mesh
          filename="package://biped_ab/meshes/base_link.STL" />
      </geometry>
      <material
        name="">
        <color
          rgba="0.792156862745098 0.819607843137255 0.933333333333333 1" />
      </material>
    </visual>
    <collision>
      <origin
        xyz="0 0 0"
        rpy="0 0 0" />
      <geometry>
        <mesh
          filename="package://biped_ab/meshes/base_link.STL" />
      </geometry>
    </collision>
  </link>
  <link
    name="ll1">
    <inertial>
      <origin
        xyz="0.0171783023443789 -0.0361498271862186 -0.0473719862653818"
        rpy="0 0 0" />
      <mass
        value="0.0567619776679607" />
      <inertia
        ixx="1.39565566149837E-05"
        ixy="-4.27357374186608E-07"
        ixz="-1.31150725972983E-06"
        iyy="2.15422046399649E-05"
        iyz="-1.04881080911904E-06"
        izz="1.15720621143436E-05" />
    </inertial>
    <visual>
      <origin
        xyz="0 0 0"
        rpy="0 0 0" />
      <geometry>
        <mesh
          filename="package://biped_ab/meshes/ll1.STL" />
      </geometry>
      <material
        name="">
        <color
          rgba="0.792156862745098 0.819607843137255 0.933333333333333 1" />
      </material>
    </visual>
    <collision>
      <origin
        xyz="0 0 0"
        rpy="0 0 0" />
      <geometry>
        <mesh
          filename="package://biped_ab/meshes/ll1.STL" />
      </geometry>
    </collision>
  </link>
  <joint
    name="cont1"
    type="revolute">
    <origin
      xyz="0.110038954635169 -0.0909144176910569 0.115414106258842"
      rpy="0 -0.00545717187650538 0" />
    <parent
      link="base_link" />
    <child
      link="ll1" />
    <axis
      xyz="0 1 0" />
    <limit
      lower="-2"
      upper="2"
      effort="5"
      velocity="1.6" />
  </joint>
  <link
    name="ll2">
    <inertial>
      <origin
        xyz="0.103549079017341 -0.0205394581648996 -0.0281541630568518"
        rpy="0 0 0" />
      <mass
        value="0.0795029659020738" />
      <inertia
        ixx="3.92910139443189E-05"
        ixy="5.63190934250085E-06"
        ixz="1.7654229543114E-05"
        iyy="4.86462440319264E-05"
        iyz="2.61796913445426E-06"
        izz="5.77024189169343E-05" />
    </inertial>
    <visual>
      <origin
        xyz="0 0 0"
        rpy="0 0 0" />
      <geometry>
        <mesh
          filename="package://biped_ab/meshes/ll2.STL" />
      </geometry>
      <material
        name="">
        <color
          rgba="0.792156862745098 0.819607843137255 0.933333333333333 1" />
      </material>
    </visual>
    <collision>
      <origin
        xyz="0 0 0"
        rpy="0 0 0" />
      <geometry>
        <mesh
          filename="package://biped_ab/meshes/ll2.STL" />
      </geometry>
    </collision>
  </link>
  <joint
    name="cont2"
    type="revolute">
    <origin
      xyz="0.0239999999999984 -0.0324493212037191 -0.0369781242816673"
      rpy="2.32915725064946 1.57079631189374 0.509524754260505" />
    <parent
      link="ll1" />
    <child
      link="ll2" />
    <axis
      xyz="1 0 0" />
    <limit
      lower="-2"
      upper="2"
      effort="5"
      velocity="1.6" />
  </joint>
  <link
    name="ll3">
    <inertial>
      <origin
        xyz="0.140666030643059 0.0270231079667057 0.0500063411660512"
        rpy="0 0 0" />
      <mass
        value="0.0795050014476073" />
      <inertia
        ixx="2.80908282137304E-05"
        ixy="-2.0873333480242E-07"
        ixz="1.90180306641402E-06"
        iyy="4.96780037376502E-05"
        iyz="5.89589606915827E-06"
        izz="6.78707430017787E-05" />
    </inertial>
    <visual>
      <origin
        xyz="0 0 0"
        rpy="0 0 0" />
      <geometry>
        <mesh
          filename="package://biped_ab/meshes/ll3.STL" />
      </geometry>
      <material
        name="">
        <color
          rgba="0.792156862745098 0.819607843137255 0.933333333333333 1" />
      </material>
    </visual>
    <collision>
      <origin
        xyz="0 0 0"
        rpy="0 0 0" />
      <geometry>
        <mesh
          filename="package://biped_ab/meshes/ll3.STL" />
      </geometry>
    </collision>
  </link>
  <joint
    name="cont3"
    type="revolute">
    <origin
      xyz="0.0895029778776613 0 0.00144799409181519"
      rpy="-3.14159265358979 0.0437737865520778 0" />
    <parent
      link="ll2" />
    <child
      link="ll3" />
    <axis
      xyz="0 1 0" />
    <limit
      lower="-2"
      upper="2"
      effort="5"
      velocity="1.6" />
  </joint>
  <link
    name="ll4">
    <inertial>
      <origin
        xyz="0.0991857622836733 0.0233913899164539 0.0334257415160589"
        rpy="0 0 0" />
      <mass
        value="0.144582107490847" />
      <inertia
        ixx="0.000251979326186154"
        ixy="-1.75099711930262E-05"
        ixz="-5.97521810663757E-05"
        iyy="0.000225480260642662"
        iyz="-4.32810518299243E-05"
        izz="9.53838179679248E-05" />
    </inertial>
    <visual>
      <origin
        xyz="0 0 0"
        rpy="0 0 0" />
      <geometry>
        <mesh
          filename="package://biped_ab/meshes/ll4.STL" />
      </geometry>
      <material
        name="">
        <color
          rgba="0.627450980392157 0.627450980392157 0.627450980392157 1" />
      </material>
    </visual>
    <collision>
      <origin
        xyz="0 0 0"
        rpy="0 0 0" />
      <geometry>
        <mesh
          filename="package://biped_ab/meshes/ll4.STL" />
      </geometry>
    </collision>
  </link>
  <joint
    name="cont4"
    type="revolute">
    <origin
      xyz="0.132403980397021 0 0.000947994091815355"
      rpy="0 -0.0441531718405978 0" />
    <parent
      link="ll3" />
    <child
      link="ll4" />
    <axis
      xyz="0 1 0" />
    <limit
      lower="-2"
      upper="2"
      effort="5"
      velocity="1.6" />
  </joint>
  <link
    name="rf1">
    <inertial>
      <origin
        xyz="-0.00755320774709644 0.0350228492921957 -0.0486303315240782"
        rpy="0 0 0" />
      <mass
        value="0.0567619776679608" />
      <inertia
        ixx="1.38859315558231E-05"
        ixy="2.27971644486845E-07"
        ixz="-1.38554215446545E-06"
        iyy="2.15606807203303E-05"
        iyz="1.00556606883407E-06"
        izz="1.16242110931389E-05" />
    </inertial>
    <visual>
      <origin
        xyz="0 0 0"
        rpy="0 0 0" />
      <geometry>
        <mesh
          filename="package://biped_ab/meshes/rf1.STL" />
      </geometry>
      <material
        name="">
        <color
          rgba="0.792156862745098 0.819607843137255 0.933333333333333 1" />
      </material>
    </visual>
    <collision>
      <origin
        xyz="0 0 0"
        rpy="0 0 0" />
      <geometry>
        <mesh
          filename="package://biped_ab/meshes/rf1.STL" />
      </geometry>
    </collision>
  </link>
  <joint
    name="cont5"
    type="revolute">
    <origin
      xyz="-0.00806104536482806 -0.0909144176910567 0.115414106258843"
      rpy="0 -0.00730289100869343 3.14159265358979" />
    <parent
      link="base_link" />
    <child
      link="rf1" />
    <axis
      xyz="0 1 0" />
    <limit
      lower="-2"
      upper="2"
      effort="5"
      velocity="1.6" />
  </joint>
  <link
    name="rf2">
    <inertial>
      <origin
        xyz="0.11540043179939 -0.0376238350796424 -0.0156001202625212"
        rpy="0 0 0" />
      <mass
        value="0.0795039655212341" />
      <inertia
        ixx="2.88332222000494E-05"
        ixy="9.39434368903839E-07"
        ixz="5.72776827871448E-06"
        iyy="4.79230445898013E-05"
        iyz="1.37251349707163E-07"
        izz="6.88825413404463E-05" />
    </inertial>
    <visual>
      <origin
        xyz="0 0 0"
        rpy="0 0 0" />
      <geometry>
        <mesh
          filename="package://biped_ab/meshes/rf2.STL" />
      </geometry>
      <material
        name="">
        <color
          rgba="0.792156862745098 0.819607843137255 0.933333333333333 1" />
      </material>
    </visual>
    <collision>
      <origin
        xyz="0 0 0"
        rpy="0 0 0" />
      <geometry>
        <mesh
          filename="package://biped_ab/meshes/rf2.STL" />
      </geometry>
    </collision>
  </link>
  <joint
    name="cont6"
    type="revolute">
    <origin
      xyz="0.0239999999999986 0.0300506787962816 -0.0365370865296178"
      rpy="-1.56981976460534 1.57079630572147 3.11555687140741" />
    <parent
      link="rf1" />
    <child
      link="rf2" />
    <axis
      xyz="1 0 0" />
    <limit
      lower="-2"
      upper="2"
      effort="5"
      velocity="1.6" />
  </joint>
  <link
    name="rf3">
    <inertial>
      <origin
        xyz="0.155250974652241 0.0390486652727043 0.0370894594273884"
        rpy="0 0 0" />
      <mass
        value="0.0795050257227758" />
      <inertia
        ixx="2.85330989780231E-05"
        ixy="-9.15840785306493E-07"
        ixz="-4.55864326505569E-06"
        iyy="4.79264241482644E-05"
        iyz="2.05884508714622E-07"
        izz="6.9179924553966E-05" />
    </inertial>
    <visual>
      <origin
        xyz="0 0 0"
        rpy="0 0 0" />
      <geometry>
        <mesh
          filename="package://biped_ab/meshes/rf3.STL" />
      </geometry>
      <material
        name="">
        <color
          rgba="0.792156862745098 0.819607843137255 0.933333333333333 1" />
      </material>
    </visual>
    <collision>
      <origin
        xyz="0 0 0"
        rpy="0 0 0" />
      <geometry>
        <mesh
          filename="package://biped_ab/meshes/rf3.STL" />
      </geometry>
    </collision>
  </link>
  <joint
    name="cont7"
    type="revolute">
    <origin
      xyz="0.08994401562971 0 0.00144799409181527"
      rpy="-3.14159265358979 -0.0624508296366413 0" />
    <parent
      link="rf2" />
    <child
      link="rf3" />
    <axis
      xyz="0 1 0" />
    <limit
      lower="-2"
      upper="2"
      effort="5"
      velocity="1.6" />
  </joint>
  <link
    name="rf4">
    <inertial>
      <origin
        xyz="0.115559425158252 0.0394490692764151 0.0397426131141088"
        rpy="0 0 0" />
      <mass
        value="0.144582107490847" />
      <inertia
        ixx="0.000271754790212108"
        ixy="4.19476010682333E-07"
        ixz="1.14513658994481E-05"
        iyy="0.000238524687661661"
        iyz="-2.42773506399403E-06"
        izz="6.25639269229725E-05" />
    </inertial>
    <visual>
      <origin
        xyz="0 0 0"
        rpy="0 0 0" />
      <geometry>
        <mesh
          filename="package://biped_ab/meshes/rf4.STL" />
      </geometry>
      <material
        name="">
        <color
          rgba="0.627450980392157 0.627450980392157 0.627450980392157 1" />
      </material>
    </visual>
    <collision>
      <origin
        xyz="0 0 0"
        rpy="0 0 0" />
      <geometry>
        <mesh
          filename="package://biped_ab/meshes/rf4.STL" />
      </geometry>
    </collision>
  </link>
  <joint
    name="cont8"
    type="revolute">
    <origin
      xyz="0.132403980397019 0 0.000947994091815521"
      rpy="0 -0.0594915261594807 0" />
    <parent
      link="rf3" />
    <child
      link="rf4" />
    <axis
      xyz="0 1 0" />
    <limit
      lower="-2"
      upper="2"
      effort="5"
      velocity="1.6" />
  </joint>
  <link
    name="box">
    <inertial>
      <origin
        xyz="-0.0688677456913595 0.0219477110981247 0.0583312662906894"
        rpy="0 0 0" />
      <mass
        value="0.612608964887326" />
      <inertia
        ixx="0.000910327254665648"
        ixy="-2.27991350048129E-06"
        ixz="1.60029178866034E-05"
        iyy="0.0012795561204698"
        iyz="-6.09825581298704E-05"
        izz="0.00185757231514542" />
    </inertial>
    <visual>
      <origin
        xyz="0 0 0"
        rpy="0 0 0" />
      <geometry>
        <mesh
          filename="package://biped_ab/meshes/box.STL" />
      </geometry>
      <material
        name="">
        <color
          rgba="0.752941176470588 0.752941176470588 0.752941176470588 1" />
      </material>
    </visual>
    <collision>
      <origin
        xyz="0 0 0"
        rpy="0 0 0" />
      <geometry>
        <mesh
          filename="package://biped_ab/meshes/box.STL" />
      </geometry>
    </collision>
  </link>
  <joint
    name="fix_f"
    type="fixed">
    <origin
      xyz="-0.00806104536482806 -0.0909144176910567 0.115414106258843"
      rpy="0 -0.00730289100869343 3.14159265358979" />
    <parent
      link="base_link" />
    <child
      link="box" />
    <axis
      xyz="0 0 0" />
  </joint>
</robot>